<?xml version="1.0"?>
<robot xmlns:xacro="http://www.ros.org/wiki/xacro">

    <xacro:macro name="insert_abb_gofa_crb15000" params="prefix parent *origin">
        <!-- BASE LINK -->
        <link name="${prefix}base">
            <visual>
                <origin xyz="0 0 0" rpy="0 0 0"/>
                <geometry>
                    <mesh filename="file://$(find abb_gofa_description)/meshes/base.dae" scale="1 1 1"/>
                </geometry>
            </visual>

            <collision>
                <origin xyz="0 0 0" rpy="0 0 0"/>
                <geometry>
                    <mesh filename="file://$(find abb_gofa_description)/meshes/base.dae" scale="1 1 1"/>
                </geometry>
            </collision>

            <inertial>
                <origin xyz="0 0 0" rpy="0 0 0"/>
                <mass value="1.0"/>
                <inertia ixx="1.0" ixy="0.0" ixz="0.0" iyy="1.0" iyz="0.0" izz="1.0"/>
            </inertial>
        </link>

        <joint name="${prefix}base_link" type="fixed">
            <parent link="${parent}"/>
            <child link="${prefix}base"/>
            <xacro:insert_block name="origin"/>
        </joint>


        <!-- LINK1 -->
        <link name="${prefix}link1">
            <visual>
                <origin xyz="0 0 0" rpy="0 0 0"/>
                <geometry>
                    <mesh filename="file://$(find abb_gofa_description)/meshes/link1.dae" scale="1 1 1"/>
                </geometry>
            </visual>

            <collision>
                <origin xyz="0 0 0" rpy="0 0 0"/>
                <geometry>
                    <mesh filename="file://$(find abb_gofa_description)/meshes/link1.dae" scale="1 1 1"/>
                </geometry>
            </collision>

            <inertial>
                <origin xyz="0 0 0" rpy="0 0 0"/>
                <mass value="1.0"/>
                <inertia ixx="1.0" ixy="0.0" ixz="0.0" iyy="1.0" iyz="0.0" izz="1.0"/>
            </inertial>
        </link>

        <joint name="${prefix}rotation_joint" type="revolute">
            <parent link="${prefix}base"/>
            <child link="${prefix}link1"/>
            <origin xyz="0 0 0.1855" rpy="0 0 0"/>
            <axis xyz="0 0 1"/>
            <limit lower="${-180*pi/180}" upper="${180*pi/180}" velocity="${125*pi/180}" effort="1000"/>
        </joint>


        <!-- LINK2 -->
        <link name="${prefix}link2">
            <visual>
                <origin xyz="0 0 0" rpy="0 0 0"/>
                <geometry>
                    <mesh filename="file://$(find abb_gofa_description)/meshes/link2.dae" scale="1 1 1"/>
                </geometry>
            </visual>

            <collision>
                <origin xyz="0 0 0" rpy="0 0 0"/>
                <geometry>
                    <mesh filename="file://$(find abb_gofa_description)/meshes/link2.dae" scale="1 1 1"/>
                </geometry>
            </collision>

            <inertial>
                <origin xyz="0 0 0" rpy="0 0 0"/>
                <mass value="1.0"/>
                <inertia ixx="1.0" ixy="0.0" ixz="0.0" iyy="1.0" iyz="0.0" izz="1.0"/>
            </inertial>
        </link>

        <joint name="${prefix}arm1_joint" type="revolute">
            <parent link="${prefix}link1"/>
            <child link="${prefix}link2"/>
            <origin xyz="0 -0.085 0.0765" rpy="0 0 0"/>
            <axis xyz="0 1 0"/>
            <limit lower="${-180*pi/180}" upper="${180*pi/180}" velocity="${125*pi/180}" effort="1000"/>
        </joint>


        <!-- LINK3 -->
        <link name="${prefix}link3">
            <visual>
                <origin xyz="0 0 0" rpy="0 0 0"/>
                <geometry>
                    <mesh filename="file://$(find abb_gofa_description)/meshes/link3.dae" scale="1 1 1"/>
                </geometry>
            </visual>

            <collision>
                <origin xyz="0 0 0" rpy="0 0 0"/>
                <geometry>
                    <mesh filename="file://$(find abb_gofa_description)/meshes/link3.dae" scale="1 1 1"/>
                </geometry>
            </collision>

            <inertial>
                <origin xyz="0 0 0" rpy="0 0 0"/>
                <mass value="1.0"/>
                <inertia ixx="1.0" ixy="0.0" ixz="0.0" iyy="1.0" iyz="0.0" izz="1.0"/>
            </inertial>
        </link>

        <joint name="${prefix}arm2_joint" type="revolute">
            <parent link="${prefix}link2"/>
            <child link="${prefix}link3"/>
            <origin xyz="0 0 0.444" rpy="0 0 0"/>
            <axis xyz="0 1 0"/>
            <limit lower="${-180*pi/180}" upper="${180*pi/180}" velocity="${125*pi/180}" effort="1000"/>
        </joint>


        <!-- LINK4 -->
        <link name="${prefix}link4">
            <visual>
                <origin xyz="0 0 0" rpy="0 0 0"/>
                <geometry>
                    <mesh filename="file://$(find abb_gofa_description)/meshes/link4.dae" scale="1 1 1"/>
                </geometry>
            </visual>

            <collision>
                <origin xyz="0 0 0" rpy="0 0 0"/>
                <geometry>
                    <mesh filename="file://$(find abb_gofa_description)/meshes/link4.dae" scale="1 1 1"/>
                </geometry>
            </collision>

            <inertial>
                <origin xyz="0 0 0" rpy="0 0 0"/>
                <mass value="1.0"/>
                <inertia ixx="1.0" ixy="0.0" ixz="0.0" iyy="1.0" iyz="0.0" izz="1.0"/>
            </inertial>
        </link>

        <joint name="${prefix}wrist_joint" type="revolute">
            <parent link="${prefix}link3"/>
            <child link="${prefix}link4"/>
            <origin xyz="0.096 0.085 0.110" rpy="0 ${pi/2} 0"/>
            <axis xyz="0 0 1"/>
            <limit lower="${-180*pi/180}" upper="${180*pi/180}" velocity="${125*pi/180}" effort="1000"/>
        </joint>


        <!-- LINK5 -->
        <link name="${prefix}link5">
            <visual>
                <origin xyz="0 0 0" rpy="0 0 0"/>
                <geometry>
                    <mesh filename="file://$(find abb_gofa_description)/meshes/link5.dae" scale="1 1 1"/>
                </geometry>
            </visual>

            <collision>
                <origin xyz="0 0 0" rpy="0 0 0"/>
                <geometry>
                    <mesh filename="file://$(find abb_gofa_description)/meshes/link5.dae" scale="1 1 1"/>
                </geometry>
            </collision>

            <inertial>
                <origin xyz="0 0 0" rpy="0 0 0"/>
                <mass value="1.0"/>
                <inertia ixx="1.0" ixy="0.0" ixz="0.0" iyy="1.0" iyz="0.0" izz="1.0"/>
            </inertial>
        </link>

        <joint name="${prefix}bend_joint" type="revolute">
            <parent link="${prefix}link4"/>
            <child link="${prefix}link5"/>
            <origin xyz="0 0.0755 0.373" rpy="0 0 0"/>
            <axis xyz="0 1 0"/>
            <limit lower="${-180*pi/180}" upper="${180*pi/180}" velocity="${125*pi/180}" effort="1000"/>
        </joint>


        <!-- LINK6 -->
        <link name="${prefix}link6">
            <visual>
                <origin xyz="0 0 0" rpy="0 0 0"/>
                <geometry>
                    <mesh filename="file://$(find abb_gofa_description)/meshes/link6.dae" scale="1 1 1"/>
                </geometry>
            </visual>

            <collision>
                <origin xyz="0 0 0" rpy="0 0 0"/>
                <geometry>
                    <mesh filename="file://$(find abb_gofa_description)/meshes/link6.dae" scale="1 1 1"/>
                </geometry>
            </collision>

            <inertial>
                <origin xyz="0 0 0" rpy="0 0 0"/>
                <mass value="1.0"/>
                <inertia ixx="1.0" ixy="0.0" ixz="0.0" iyy="1.0" iyz="0.0" izz="1.0"/>
            </inertial>
        </link>

        <joint name="${prefix}turn_joint" type="revolute">
            <parent link="${prefix}link5"/>
            <child link="${prefix}link6"/>
            <origin xyz="-0.080 -0.0745 0.068" rpy="0 0 0"/>
            <axis xyz="0 0 1"/>
            <limit lower="${-180*pi/180}" upper="${180*pi/180}" velocity="${125*pi/180}" effort="1000"/>
        </joint>


        <!-- TOOL EEF -->
        <link name="${prefix}tool_eef"/>

        <joint name="${prefix}tool_eef_fixed_joint" type="fixed">
            <parent link="${prefix}link6"/>
            <child link="${prefix}tool_eef"/>
            <origin xyz="0 0 0.0326" rpy="0 0 0"/>
        </joint>

    </xacro:macro>
</robot>